[2024-03-07T05:22:42.984+0000] {task_context_logger.py:104} ERROR - Executor reports task instance <TaskInstance: welcome_dag.print_welcome manual__2024-03-07T05:22:38.540440+00:00 [queued]> finished (failed) although the task says it's queued. (Info: None) Was the task killed externally?
