[2024-03-07T05:08:56.682+0000] {taskinstance.py:1979} INFO - Dependencies all met for dep_context=non-requeueable deps ti=<TaskInstance: welcome_dag.print_date manual__2024-03-07T05:08:46.701275+00:00 [queued]>
[2024-03-07T05:08:56.711+0000] {taskinstance.py:1979} INFO - Dependencies all met for dep_context=requeueable deps ti=<TaskInstance: welcome_dag.print_date manual__2024-03-07T05:08:46.701275+00:00 [queued]>
[2024-03-07T05:08:56.712+0000] {taskinstance.py:2193} INFO - Starting attempt 1 of 1
[2024-03-07T05:08:56.807+0000] {taskinstance.py:2214} INFO - Executing <Task(PythonOperator): print_date> on 2024-03-07 05:08:46.701275+00:00
[2024-03-07T05:08:56.812+0000] {standard_task_runner.py:60} INFO - Started process 145 to run task
[2024-03-07T05:08:56.816+0000] {standard_task_runner.py:87} INFO - Running: ['airflow', 'tasks', 'run', 'welcome_dag', 'print_date', 'manual__2024-03-07T05:08:46.701275+00:00', '--job-id', '17', '--raw', '--subdir', 'DAGS_FOLDER/welcome.py', '--cfg-path', '/tmp/tmpa4ahs83z']
[2024-03-07T05:08:56.820+0000] {standard_task_runner.py:88} INFO - Job 17: Subtask print_date
[2024-03-07T05:08:57.030+0000] {task_command.py:423} INFO - Running <TaskInstance: welcome_dag.print_date manual__2024-03-07T05:08:46.701275+00:00 [running]> on host 0448addf720a
[2024-03-07T05:08:57.392+0000] {taskinstance.py:2510} INFO - Exporting env vars: AIRFLOW_CTX_DAG_OWNER='airflow' AIRFLOW_CTX_DAG_ID='welcome_dag' AIRFLOW_CTX_TASK_ID='print_date' AIRFLOW_CTX_EXECUTION_DATE='2024-03-07T05:08:46.701275+00:00' AIRFLOW_CTX_TRY_NUMBER='1' AIRFLOW_CTX_DAG_RUN_ID='manual__2024-03-07T05:08:46.701275+00:00'
[2024-03-07T05:08:57.396+0000] {taskinstance.py:2728} ERROR - Task failed with exception
Traceback (most recent call last):
  File "/home/airflow/.local/lib/python3.11/site-packages/airflow/models/taskinstance.py", line 444, in _execute_task
    result = _execute_callable(context=context, **execute_callable_kwargs)
             ^^^^^^^^^^^^^^^^^^^^^^^^^^^^^^^^^^^^^^^^^^^^^^^^^^^^^^^^^^^^^
  File "/home/airflow/.local/lib/python3.11/site-packages/airflow/models/taskinstance.py", line 414, in _execute_callable
    return execute_callable(context=context, **execute_callable_kwargs)
           ^^^^^^^^^^^^^^^^^^^^^^^^^^^^^^^^^^^^^^^^^^^^^^^^^^^^^^^^^^^^
  File "/home/airflow/.local/lib/python3.11/site-packages/airflow/operators/python.py", line 200, in execute
    return_value = self.execute_callable()
                   ^^^^^^^^^^^^^^^^^^^^^^^
  File "/home/airflow/.local/lib/python3.11/site-packages/airflow/operators/python.py", line 217, in execute_callable
    return self.python_callable(*self.op_args, **self.op_kwargs)
           ^^^^^^^^^^^^^^^^^^^^^^^^^^^^^^^^^^^^^^^^^^^^^^^^^^^^^
  File "/opt/airflow/dags/welcome.py", line 31, in print_date
    print('Today is {}'.format(datetime.today().date()))
                               ^^^^^^^^
NameError: name 'datetime' is not defined
[2024-03-07T05:08:57.452+0000] {taskinstance.py:1149} INFO - Marking task as FAILED. dag_id=welcome_dag, task_id=print_date, execution_date=20240307T050846, start_date=20240307T050856, end_date=20240307T050857
[2024-03-07T05:08:57.564+0000] {standard_task_runner.py:107} ERROR - Failed to execute job 17 for task print_date (name 'datetime' is not defined; 145)
[2024-03-07T05:08:57.593+0000] {local_task_job_runner.py:234} INFO - Task exited with return code 1
[2024-03-07T05:08:57.656+0000] {taskinstance.py:3309} INFO - 0 downstream tasks scheduled from follow-on schedule check
